2025-05-30 10:45:56,768 [INFO] Found credentials in shared credentials file: ~/.aws/credentials
2025-05-30 10:45:57,098 [INFO] Successfully loaded model: models/logistic_regression.pkl
2025-05-30 10:46:03,016 [INFO] Successfully loaded model: models/random_forest.pkl
2025-05-30 10:46:04,325 [INFO] Successfully loaded model: models/xgboost.pkl
2025-05-30 10:48:35,726 [INFO] Found credentials in shared credentials file: ~/.aws/credentials
2025-05-30 10:48:36,185 [ERROR] Failed to load model xgboost: An error occurred (AccessDenied) when calling the GetObject operation: Access Denied
Traceback (most recent call last):
  File "/Users/apple/Desktop/25 Spring/Cloud/Final Proj/app.py", line 160, in load_model_from_s3
    response = s3.get_object(Bucket=BUCKET, Key=model_key)
  File "/Users/apple/miniforge3/envs/clouda2/lib/python3.10/site-packages/botocore/client.py", line 595, in _api_call
    return self._make_api_call(operation_name, kwargs)
  File "/Users/apple/miniforge3/envs/clouda2/lib/python3.10/site-packages/botocore/context.py", line 123, in wrapper
    return func(*args, **kwargs)
  File "/Users/apple/miniforge3/envs/clouda2/lib/python3.10/site-packages/botocore/client.py", line 1058, in _make_api_call
    raise error_class(parsed_response, operation_name)
botocore.exceptions.ClientError: An error occurred (AccessDenied) when calling the GetObject operation: Access Denied

2025-05-30 10:50:56,845 [INFO] Found credentials in shared credentials file: ~/.aws/credentials
2025-05-30 10:50:56,996 [ERROR] Failed to load model xgboost: An error occurred (AccessDenied) when calling the GetObject operation: Access Denied
Traceback (most recent call last):
  File "/Users/apple/Desktop/25 Spring/Cloud/Final Proj/app.py", line 160, in load_model_from_s3
    response = s3.get_object(Bucket=BUCKET, Key=model_key)
  File "/Users/apple/miniforge3/envs/clouda2/lib/python3.10/site-packages/botocore/client.py", line 595, in _api_call
    return self._make_api_call(operation_name, kwargs)
  File "/Users/apple/miniforge3/envs/clouda2/lib/python3.10/site-packages/botocore/context.py", line 123, in wrapper
    return func(*args, **kwargs)
  File "/Users/apple/miniforge3/envs/clouda2/lib/python3.10/site-packages/botocore/client.py", line 1058, in _make_api_call
    raise error_class(parsed_response, operation_name)
botocore.exceptions.ClientError: An error occurred (AccessDenied) when calling the GetObject operation: Access Denied

2025-05-30 10:52:05,000 [INFO] Found credentials in shared credentials file: ~/.aws/credentials
2025-05-30 10:52:05,281 [INFO] Successfully loaded model: models/xgboost.pkl
2025-05-30 12:06:17,175 [INFO] Found credentials in shared credentials file: ~/.aws/credentials
2025-05-30 12:06:17,569 [INFO] Successfully loaded model: models/xgboost.pkl
